<?xml version="1.0" ?>
<!-- =================================================================================== -->
<!-- |    This document was autogenerated by xacro from /home/core-robotics/catkin_ws/src/Wheelchair-Tennis-Robot/wam_model/robots/wam7.urdf.xacro | -->
<!-- |    EDITING THIS FILE BY HAND IS NOT RECOMMENDED                                 | -->
<!-- =================================================================================== -->
<robot name="wam">
  <gazebo>
    <plugin filename="libgazebo_ros_control.so" name="gazebo_ros_control">
      <robotNamespace>/</robotNamespace>
    </plugin>
  </gazebo>
  <!-- Tennis Net -->
  <!-- <xacro:macro name="tennis_net" params="parent_link" >
    <joint name="net_joint" type="fixed">
      <parent link="${parent_link}"/>
      <child link="net_link"/>
      <origin xyz="11.885 0 0.535" rpy="0 0 0"/>
    </joint>
    <link name="net_link">
      <visual>
          <material name="White">
            <color rgba="1 1 1 0.9"/>
          </material>
          <origin xyz="0 6.4 -0.535" rpy="${PI/2} 0 ${-PI/2}" />
          <geometry>
            <mesh filename="${models_path}/sw_meshes/net_4.STL" scale="0.001 0.001 0.001"/>
          </geometry>
        </visual>
    </link>
  </xacro:macro> -->
  <!-- SICK LiDAR -->
  <!-- <xacro:macro name="lidar" params="prefix">
    <link name="${prefix}/lidar_link" />
    <joint name="${prefix}/lidar_joint" type="fixed">
      <parent link="${prefix}/wheelchair_link"/>
      <child link="${prefix}/lidar_link"/>
      <origin xyz="0.2709589 0 -0.0866" rpy="0 0 0"/>
    </joint>
  </xacro:macro> -->
  <!-- Wheelchair Rollers -->
  <!-- <xacro:macro name="wheelchair_roller" params="prefix name xyz">
    <joint name="${prefix}/${name}_joint" type="continuous">
      <parent link="base_link"/>
      <child link="${prefix}/${name}_link"/>
      <origin xyz="${xyz}" rpy="${PI/2} 0 0"/>
      <axis xyz="0 0 1"/>
    </joint>
    <link name="${prefix}/${name}_link" >
        <inertial>
        <mass value="1"/>
        <inertia ixx="0.0001" ixy="0" ixz="0" iyy="0.0001" iyz="0" izz="0.0001"/>
      </inertial>
      <visual>
        <geometry>
           <cylinder length="0.01" radius="0.03"/>
        </geometry>
      </visual>
      <collision>
        <geometry>
          <cylinder length="0.01" radius="0.03"/>
        </geometry>
        <surface>
        <friction>
          <ode>
            <mu>0</mu>
            <mu2>0</mu2>
          </ode>
        </friction>
      </surface>
      </collision>
    </link>
    <xacro:effort_transmission prefix="${prefix}/${name}"/>
  </xacro:macro>

  <xacro:macro name="wheelchair_rollers" params="prefix">
    <xacro:wheelchair_roller prefix="${prefix}" name="FL_roller" xyz=" 0.18  0.26 -0.44"/>
    <xacro:wheelchair_roller prefix="${prefix}" name="FR_roller" xyz=" 0.18 -0.26 -0.44"/>
    <xacro:wheelchair_roller prefix="${prefix}" name="BC_roller" xyz="-0.39     0 -0.43"/>
  </xacro:macro> -->
  <!-- Wheelchair Wheels -->
  <!-- <xacro:macro name="wheelchair_wheel" params="prefix name xyz rpy">
    <joint name="${name}_joint" type="fixed">
      <parent link="base_link"/>
      <child link="${name}_link"/>
      <origin xyz="${xyz}" rpy="${rpy}"/>
      <axis xyz="0 0 1"/>
    </joint>
    <link name="${name}_link">
      <inertial>
        <mass value="4"/>
        <inertia ixx="0.0001" ixy="0" ixz="0" iyy="0.0001" iyz="0" izz="0.0001"/>
      </inertial>
      <visual>
        <geometry>
           <cylinder length="0.01" radius="0.25"/>
        </geometry>
      </visual>
      <collision>
        <geometry>
          <cylinder length="0.01" radius="0.25"/>
        </geometry>
        <surface>
        <friction>
          <ode>
            <mu>1</mu>
            <mu2>1</mu2>
          </ode>
        </friction>
      </surface>
      </collision>
    </link>
    <xacro:effort_transmission prefix="${prefix}/${name}"/>
  </xacro:macro> -->
  <!-- <xacro:macro name="wheelchair_wheels" params="prefix">
    <xacro:wheelchair_wheel prefix="${prefix}" name="wheel_right" xyz="-0.12 -0.5 -0.22" rpy="${-PI/2}  0.0 0.0"/>
    <xacro:wheelchair_wheel prefix="${prefix}" name="wheel_left" xyz="-0.12  0.5 -0.22" rpy="${-PI/2}  0.0 0.0"/>

  </xacro:macro> -->
  <!-- Hollow forearm macros -->
  <!--<xacro:macro name="wam_hollow_forearm" params="prefix">-->
  <!--<joint name="${prefix}/elbow_joint" type="revolute">-->
  <!--<parent link="${prefix}/upper_arm_link"/>-->
  <!--<child link="${prefix}/forearm_link"/>-->
  <!--<origin xyz="0.045 -0.55 0" rpy="${0.5 * PI} 0 0"/>-->
  <!--<axis xyz="0 1 0"/>-->
  <!--<limit effort="15" lower="-0.9" upper="${PI}" velocity="0.50"/>-->
  <!--[> <safety_controller k_position="100" k_velocity="3" soft_lower_limit="-100.0" soft_upper_limit="100.0" /> <]-->
  <!--<dynamics damping="0.1" friction="100.0"/>-->
  <!--</joint>-->
  <!--<link name="${prefix}/forearm_link" >-->
  <!--<inertial>-->
  <!--<origin xyz="0 0 0" />-->
  <!--<mass value="3.20016804" />-->
  <!--<origin xyz="-0.04001488 -.00022942 .13271662" rpy="0 0 0" />-->
  <!--<inertia  ixx="0.01491672" ixy="0.00001741"   ixz="-0.00150604"-->
  <!--iyy="0.01482988"   iyz="-0.00002109"-->
  <!--izz="0.00294463" />-->
  <!--</inertial>-->
  <!--<visual>-->
  <!--<material name="WAMGrey">-->
  <!--<color rgba="0.7 0.7 0.7 1.0"/>-->
  <!--</material>-->
  <!--<origin xyz="0 0 0" rpy="-${PI} 0 0" />-->
  <!--<geometry>-->
  <!--<mesh filename="${models_path}/meshes/wamForeArmLink4.DAE"/>-->
  <!--</geometry>-->
  <!--</visual>-->
  <!--<collision>-->
  <!--<origin xyz="0 0 0" rpy="-${PI} 0 0" />-->
  <!--<geometry>-->
  <!--<mesh filename="${models_path}/meshes/wamForeArmLink4.stl"/>-->
  <!--</geometry>-->
  <!--</collision>-->
  <!--</link>-->
  <!--</xacro:macro>-->
  <!--<xacro:macro name="wam_hollow_wrist" params="prefix">-->
  <!--<joint name="${prefix}/UpperWristJoint" type="fixed">-->
  <!--<parent link="${prefix}/ForeArmLink"/>-->
  <!--<child link="${prefix}/LowerWristPalmLink"/>-->
  <!--<origin xyz="-0.045 0 .35" rpy="-${0.5 * PI} 0 ${0.5 * PI}"/>-->
  <!--<axis xyz="0 -1 0"/>-->
  <!--<limit effort="5" lower="-4.8" upper="1.3" velocity="0.20"/>-->
  <!--[> <safety_controller k_position="100" k_velocity="3" soft_lower_limit="-100.0" soft_upper_limit="100.0" /> <]-->
  <!--<dynamics damping="0.1" friction="100.0"/>-->
  <!--</joint>-->
  <!--<link name="${prefix}/LowerWristPalmLink" >-->
  <!--<inertial>-->
  <!--<origin xyz="0.00008921 0.00511217 0.00435824" />-->
  <!--<mass value="1.12376019" />-->
  <!--<inertia  ixx="0.00005029" ixy="0.00000020"  ixz="0.00007582"-->
  <!--iyy="0.00007582"  iyz="-0.00000359"-->
  <!--izz="0.00006270" />-->
  <!--</inertial>-->
  <!--<visual>-->
  <!--<material name="WAMGrey">-->
  <!--<color rgba="0.7 0.7 0.7 1.0"/>-->
  <!--</material>-->
  <!--<origin xyz="0 0.02711 0" rpy="${PI} 0 0" />-->
  <!--<geometry>-->
  <!--<mesh filename="${models_path}/meshes/wamUpperWristYawLink.DAE"/>-->
  <!--</geometry>-->
  <!--</visual>-->
  <!--<collision>-->
  <!--<origin xyz="0 0.02711 0" rpy="${PI} 0 0" />-->
  <!--<geometry>-->
  <!--<mesh filename="${models_path}/meshes/wamUpperWristYawLink5.stl"/>-->
  <!--</geometry>-->
  <!--</collision>-->
  <!--</link>-->
  <!--</xacro:macro>-->
  <!-- Palm with ForceTorque macros -->
  <!--<xacro:macro name="LowerWristFT" params="prefix">-->
  <!--<joint name="${prefix}/LowerWristYawJoint" type="revolute">-->
  <!--<parent link="${prefix}/UpperWristPitchLink"/>-->
  <!--<child link="${prefix}/LowerWristYawLink"/>-->
  <!--<origin xyz="0 0 0.06713340" rpy="0 0 0"/>-->
  <!--<axis xyz="0 0 1"/>-->
  <!--<limit effort="5" lower="-2.95" upper="2.95" velocity="0.20"/>[> 2.95 is a limit taken in from 3 due to saftey and differences between arms. <]-->
  <!--[> <safety_controller k_position="100" k_velocity="3" soft_lower_limit="-100.0" soft_upper_limit="100.0" /> <]-->
  <!--<dynamics damping="0.1" friction="100.0"/>-->
  <!--</joint>-->
  <!--<link name="${prefix}/LowerWristYawLink" >-->
  <!--<inertial>-->
  <!--<origin xyz="-0.00000134 -0.00228167 -0.00000141" rpy="0 0 0" />-->
  <!--<mass value="0.17286134" />-->
  <!--<inertia  ixx="0.00010859" ixy="0.00000000"  ixz="-0.00000000"-->
  <!--iyy="0.00020683"  iyz="-0.0000000"-->
  <!--izz="0.00010851" />-->
  <!--</inertial>-->
  <!--<visual>-->
  <!--<material name="WAMGrey">-->
  <!--<color rgba="0.7 0.7 0.7 1.0"/>-->
  <!--</material>-->
  <!--<origin xyz="0 0 0" rpy="0 0 0" />-->
  <!--<geometry>-->
  <!--<mesh filename="${models_path}/meshes/forceTorqueSensor.DAE"/>-->
  <!--</geometry>-->
  <!--</visual>-->
  <!--<collision>-->
  <!--<origin xyz="0 0 0" rpy="0 0 0" />-->
  <!--<geometry>-->
  <!--<mesh filename="${models_path}/meshes/forceTorqueSensor.stl"/>-->
  <!--</geometry>-->
  <!--</collision>-->
  <!--</link>-->
  <!--</xacro:macro>-->
  <!-- Materials -->
  <material name="WAMGrey">
    <!-- <color rgba="0.7 0.7 0.7 1.0"/> -->
    <color rgba="0.827 0.329 0.0 1.0"/>
  </material>
  <!-- Root link is in the world frame-->
  <!-- <link name="static_link"/> -->
  <link name="base_link"/>
  <link name="base_footprint"/>
  <!-- <joint name="fixed_world_joint" type="floating">
    <parent link="static_link"/>
    <child link="base_footprint"/>
    <origin xyz="0 0 0" rpy="0 0 0"/>
  </joint> -->
  <joint name="base_link_joint" type="fixed">
    <parent link="base_footprint"/>
    <child link="base_link"/>
    <origin rpy="0 0 0" xyz="0 0 0.49"/>
  </joint>
  <joint name="wam/wam_fixed_joint" type="fixed">
    <parent link="base_link"/>
    <child link="wam/base_link"/>
    <origin rpy="0 0 3.141592653589793" xyz=".0793752 0.0 0.001"/>
  </joint>
  <gazebo reference="wam/base_link">
    <material>Gazebo/Grey</material>
  </gazebo>
  <link name="wam/base_link">
    <inertial>
      <origin xyz="0.1 0 0"/>
      <mass value=".1"/>
      <inertia ixx="0.1" ixy="0" ixz="0" iyy="0.1" iyz="0" izz="0.1"/>
    </inertial>
    <visual>
      <material name="WAMGrey">
        <color rgba="0.7 0.7 0.7 0.0"/>
      </material>
      <geometry>
        <mesh filename="package://wam_model/models/sw_meshes/base_link_fine.stl"/>
      </geometry>
    </visual>
    <collision>
      <geometry>
        <mesh filename="package://wam_model/models/sw_meshes/base_link_convex.dae"/>
      </geometry>
    </collision>
  </link>
  <joint name="wam/base_yaw_joint" type="revolute">
    <parent link="wam/base_link"/>
    <child link="wam/shoulder_yaw_link"/>
    <origin rpy="0 0 0" xyz="0 0 0.346"/>
    <axis xyz="0 0 1"/>
    <limit effort="53" lower="-2.6" upper="2.6" velocity="10.0"/>
    <dynamics damping="0.9" friction="0"/>
  </joint>
  <gazebo reference="wam/base_yaw_joint">
    <!-- <provideFeedback>true</provideFeedback>
    <implicitSpringDamper>true</implicitSpringDamper> -->
    <!--<kp>0.0</kp>[> CFM <]-->
    <!--<kd>0.0</kd>[> ERP <]-->
    <!--<cfmDamping>true</cfmDamping>-->
    <!--<dynamics damping="5.5" friction="1"/>-->
  </gazebo>
  <transmission name="wam/base_yaw_trans">
    <type>transmission_interface/SimpleTransmission</type>
    <joint name="wam/base_yaw_joint">
      <hardwareInterface>hardware_interface/PositionJointInterface</hardwareInterface>
    </joint>
    <actuator name="wam/base_yaw_motor">
      <hardwareInterface>hardware_interface/PositionJointInterface</hardwareInterface>
      <mechanicalReduction>1</mechanicalReduction>
    </actuator>
  </transmission>
  <gazebo reference="wam/shoulder_yaw_link">
    <material>Gazebo/Grey</material>
  </gazebo>
  <link name="wam/shoulder_yaw_link">
    <inertial>
      <origin xyz="-.00443422 -.00066489 -0.1289039 "/>
      <mass value="0.0001"/>
      <inertia ixx=".13488033" ixy="-0.00012485" ixz="0.00213041" iyy=".09046330" iyz="-.00068555" izz=".11328369"/>
    </inertial>
    <visual>
      <material name="WAMGrey">
        <color rgba="0.7 0.7 0.7 1.0"/>
      </material>
      <geometry>
        <mesh filename="package://wam_model/models/sw_meshes/shoulder_link_fine.stl"/>
      </geometry>
    </visual>
    <collision>
      <geometry>
        <mesh filename="package://wam_model/models/sw_meshes/shoulder_link_convex_decomposition.dae"/>
      </geometry>
    </collision>
  </link>
  <joint name="wam/shoulder_pitch_joint" type="revolute">
    <parent link="wam/shoulder_yaw_link"/>
    <child link="wam/shoulder_pitch_link"/>
    <origin rpy="-1.5707963267948966 0 0" xyz="0 0 0"/>
    <axis xyz="0 0 1"/>
    <limit effort="53" lower="-2" upper="2" velocity="10"/>
    <dynamics damping="0.25" friction="0"/>
  </joint>
  <gazebo reference="wam/shoulder_pitch_joint">
    <!-- <provideFeedback>true</provideFeedback>
    <implicitSpringDamper>true</implicitSpringDamper> -->
    <!--<kp>0.0</kp>[> CFM <]-->
    <!--<kd>0.0</kd>[> ERP <]-->
    <!--<cfmDamping>true</cfmDamping>-->
    <!--<dynamics damping="5.5" friction="1"/>-->
  </gazebo>
  <transmission name="wam/shoulder_pitch_trans">
    <type>transmission_interface/SimpleTransmission</type>
    <joint name="wam/shoulder_pitch_joint">
      <hardwareInterface>hardware_interface/PositionJointInterface</hardwareInterface>
    </joint>
    <actuator name="wam/shoulder_pitch_motor">
      <hardwareInterface>hardware_interface/PositionJointInterface</hardwareInterface>
      <mechanicalReduction>1</mechanicalReduction>
    </actuator>
  </transmission>
  <gazebo reference="wam/shoulder_pitch_link">
    <material>Gazebo/Grey</material>
  </gazebo>
  <link name="wam/shoulder_pitch_link">
    <visual>
      <material name="WAMGrey">
        <color rgba="0.7 0.7 0.7 1.0"/>
      </material>
      <geometry>
        <mesh filename="package://wam_model/models/sw_meshes/shoulder_pitch_link_fine.stl"/>
      </geometry>
    </visual>
    <inertial>
      <origin xyz="-.00236981 -.01542114 .03105614 "/>
      <mass value="0.0001"/>
      <inertia ixx="0.02140958" ixy="-0.00002461" ixz="0.00027172" iyy="0.015589060" iyz="0.0018192" izz="0.01377875"/>
    </inertial>
    <collision>
      <geometry>
        <mesh filename="package://wam_model/models/sw_meshes/shoulder_pitch_link_convex.dae"/>
      </geometry>
    </collision>
  </link>
  <joint name="wam/shoulder_yaw_joint" type="revolute">
    <parent link="wam/shoulder_pitch_link"/>
    <child link="wam/upper_arm_link"/>
    <origin rpy="1.5707963267948966 0 0" xyz="0 0 0"/>
    <axis xyz="0 0 1"/>
    <limit effort="45" lower="-2.8" upper="2.8" velocity="10"/>
    <dynamics damping="0.75" friction="0"/>
  </joint>
  <gazebo reference="wam/shoulder_yaw_joint">
    <!-- <provideFeedback>true</provideFeedback>
    <implicitSpringDamper>true</implicitSpringDamper> -->
    <!--<kp>0.0</kp>[> CFM <]-->
    <!--<kd>0.0</kd>[> ERP <]-->
    <!--<cfmDamping>true</cfmDamping>-->
    <!--<dynamics damping="5.5" friction="1"/>-->
  </gazebo>
  <transmission name="wam/shoulder_yaw_trans">
    <type>transmission_interface/SimpleTransmission</type>
    <joint name="wam/shoulder_yaw_joint">
      <hardwareInterface>hardware_interface/PositionJointInterface</hardwareInterface>
    </joint>
    <actuator name="wam/shoulder_yaw_motor">
      <hardwareInterface>hardware_interface/PositionJointInterface</hardwareInterface>
      <mechanicalReduction>1</mechanicalReduction>
    </actuator>
  </transmission>
  <gazebo reference="wam/upper_arm_link">
    <material>Gazebo/Grey</material>
  </gazebo>
  <link name="wam/upper_arm_link">
    <inertial>
      <origin xyz="0.00683258580000000 0.000033090000000 0.392492300000000"/>
      <mass value="0.0001"/>
      <inertia ixx=".05911077" ixy="-0.00000738" ixz="-0.00249612" iyy="0.05927043" iyz="0.00001767" izz="0.0032455"/>
    </inertial>
    <visual>
      <material name="WAMGrey">
        <color rgba="0.7 0.7 0.7 1.0"/>
      </material>
      <geometry>
        <mesh filename="package://wam_model/models/sw_meshes/upper_arm_link_fine.stl"/>
      </geometry>
    </visual>
    <collision>
      <geometry>
        <mesh filename="package://wam_model/models/sw_meshes/upper_arm_link_convex_decomposition.dae"/>
      </geometry>
    </collision>
  </link>
  <joint name="wam/elbow_pitch_joint" type="revolute">
    <parent link="wam/upper_arm_link"/>
    <child link="wam/forearm_link"/>
    <origin rpy="-1.5707963267948966 0 0" xyz="0.045 0 0.55"/>
    <axis xyz="0 0 1"/>
    <limit effort="30" lower="-0.9" upper="3.3415926535897933" velocity="10"/>
    <dynamics damping="0.4" friction="0"/>
  </joint>
  <gazebo reference="wam/elbow_pitch_joint">
    <!-- <provideFeedback>true</provideFeedback>
    <implicitSpringDamper>true</implicitSpringDamper> -->
    <!--<kp>0.0</kp>[> CFM <]-->
    <!--<kd>0.0</kd>[> ERP <]-->
    <!--<cfmDamping>true</cfmDamping>-->
    <!--<dynamics damping="5.5" friction="1"/>-->
  </gazebo>
  <transmission name="wam/elbow_pitch_trans">
    <type>transmission_interface/SimpleTransmission</type>
    <joint name="wam/elbow_pitch_joint">
      <hardwareInterface>hardware_interface/PositionJointInterface</hardwareInterface>
    </joint>
    <actuator name="wam/elbow_pitch_motor">
      <hardwareInterface>hardware_interface/PositionJointInterface</hardwareInterface>
      <mechanicalReduction>1</mechanicalReduction>
    </actuator>
  </transmission>
  <gazebo reference="wam/forearm_link">
    <material>Gazebo/Grey</material>
  </gazebo>
  <link name="wam/forearm_link">
    <inertial>
      <mass value="0.0001"/>
      <origin rpy="0 0 0" xyz="-0.04001488 -.14271662 -.00022942 "/>
      <inertia ixx="0.01491672" ixy="0.001506040000000" ixz="0.000017410000000" iyy="0.002944630000000" iyz="0.000021090000000" izz="0.014829880000000"/>
    </inertial>
    <visual>
      <material name="WAMGrey">
        <color rgba="0.7 0.7 0.7 1.0"/>
      </material>
      <geometry>
        <mesh filename="package://wam_model/models/sw_meshes/elbow_link_fine.stl"/>
      </geometry>
    </visual>
    <collision>
      <geometry>
        <mesh filename="package://wam_model/models/sw_meshes/elbow_link_convex.dae"/>
      </geometry>
    </collision>
    <visual>
      <material name="WAMGrey">
        <color rgba="0.7 0.7 0.7 1.0"/>
      </material>
      <origin rpy="1.5707963267948966 0 0" xyz="-0.045 -0.0730 0"/>
      <geometry>
        <mesh filename="package://wam_model/models/sw_meshes/forearm_link_fine.stl"/>
      </geometry>
    </visual>
    <collision>
      <origin rpy="1.5707963267948966 0 0" xyz="-0.045 -0.0730 0"/>
      <geometry>
        <mesh filename="package://wam_model/models/sw_meshes/forearm_link_convex_decomposition.dae"/>
      </geometry>
    </collision>
  </link>
  <joint name="wam/wrist_yaw_joint" type="revolute">
    <parent link="wam/forearm_link"/>
    <child link="wam/wrist_yaw_link"/>
    <origin rpy="1.5707963267948966 3.141592653589793 0" xyz="-0.045 -0.3 0"/>
    <axis xyz="0 0 1"/>
    <limit effort="10" lower="-4.55" upper="1.35" velocity="10"/>
    <dynamics damping="0.25" friction="0"/>
  </joint>
  <gazebo reference="wam/wrist_yaw_joint">
    <!-- <provideFeedback>true</provideFeedback>
    <implicitSpringDamper>true</implicitSpringDamper> -->
    <!--<kp>0.0</kp>[> CFM <]-->
    <!--<kd>0.0</kd>[> ERP <]-->
    <!--<cfmDamping>true</cfmDamping>-->
    <!--<dynamics damping="5.5" friction="1"/>-->
  </gazebo>
  <transmission name="wam/wrist_yaw_trans">
    <type>transmission_interface/SimpleTransmission</type>
    <joint name="wam/wrist_yaw_joint">
      <hardwareInterface>hardware_interface/PositionJointInterface</hardwareInterface>
    </joint>
    <actuator name="wam/wrist_yaw_motor">
      <hardwareInterface>hardware_interface/PositionJointInterface</hardwareInterface>
      <mechanicalReduction>1</mechanicalReduction>
    </actuator>
  </transmission>
  <gazebo reference="wam/wrist_yaw_link">
    <material>Gazebo/Grey</material>
  </gazebo>
  <link name="wam/wrist_yaw_link">
    <inertial>
      <origin xyz="0.00008921 0.00435824 -0.00511217 "/>
      <mass value="0.0001"/>
      <inertia ixx="0.00005029" ixy="0.00000020" ixz="0.00007582" iyy="0.00007582" iyz="-0.00000359" izz="0.00006270"/>
    </inertial>
    <visual>
      <material name="WAMGrey">
        <color rgba="0.7 0.7 0.7 1.0"/>
      </material>
      <origin rpy="0 0 0" xyz="0 0 0"/>
      <geometry>
        <mesh filename="package://wam_model/models/sw_meshes/wrist_yaw_link_fine.stl"/>
      </geometry>
    </visual>
    <collision>
      <origin rpy="0 0 0" xyz="0 0 0"/>
      <geometry>
        <mesh filename="package://wam_model/models/sw_meshes/wrist_yaw_link_convex_decomposition.dae"/>
      </geometry>
    </collision>
  </link>
  <joint name="wam/wrist_pitch_joint" type="revolute">
    <parent link="wam/wrist_yaw_link"/>
    <child link="wam/wrist_pitch_link"/>
    <origin rpy="-1.5707963267948966 0 3.141592653589793" xyz="0 0 0"/>
    <axis xyz="0 0 1"/>
    <limit effort="10" lower="-1.5707" upper="1.5707" velocity="10"/>
    <dynamics damping="0.05" friction="0"/>
  </joint>
  <gazebo reference="wam/wrist_pitch_joint">
    <!-- <provideFeedback>true</provideFeedback>
    <implicitSpringDamper>true</implicitSpringDamper> -->
    <!--<kp>0.0</kp>[> CFM <]-->
    <!--<kd>0.0</kd>[> ERP <]-->
    <!--<cfmDamping>true</cfmDamping>-->
    <!--<dynamics damping="5.5" friction="1"/>-->
  </gazebo>
  <transmission name="wam/wrist_pitch_trans">
    <type>transmission_interface/SimpleTransmission</type>
    <joint name="wam/wrist_pitch_joint">
      <hardwareInterface>hardware_interface/PositionJointInterface</hardwareInterface>
    </joint>
    <actuator name="wam/wrist_pitch_motor">
      <hardwareInterface>hardware_interface/PositionJointInterface</hardwareInterface>
      <mechanicalReduction>1</mechanicalReduction>
    </actuator>
  </transmission>
  <gazebo reference="wam/wrist_pitch_link">
    <material>Gazebo/Grey</material>
  </gazebo>
  <link name="wam/wrist_pitch_link">
    <inertial>
      <origin rpy="0 0 0" xyz="-0.00012262 -0.02468336 -0.01703194 "/>
      <mass value="0.0001"/>
      <inertia ixx="0.00055516" ixy="0.00000061" ixz="-0.00000074" iyy="0.00024367" iyz="-0.00004590" izz="0.00045358"/>
    </inertial>
    <visual>
      <material name="WAMGrey">
        <color rgba="0.7 0.7 0.7 1.0"/>
      </material>
      <geometry>
        <mesh filename="package://wam_model/models/sw_meshes/wrist_pitch_link_fine.stl"/>
      </geometry>
    </visual>
    <collision>
      <geometry>
        <mesh filename="package://wam_model/models/sw_meshes/wrist_pitch_link_convex_decomposition.dae"/>
      </geometry>
    </collision>
  </link>
  <joint name="wam/palm_yaw_joint" type="revolute">
    <parent link="wam/wrist_pitch_link"/>
    <child link="wam/wrist_palm_link"/>
    <origin rpy="1.5707963267948966 0 0" xyz="0 0 0"/>
    <axis xyz="0 0 1"/>
    <limit effort="10" lower="-2.95" upper="2.95" velocity="10"/>
    <dynamics damping="0.05" friction="0"/>
  </joint>
  <gazebo reference="wam/palm_yaw_joint">
    <!-- <provideFeedback>true</provideFeedback>
    <implicitSpringDamper>true</implicitSpringDamper> -->
    <!--<kp>0.0</kp>[> CFM <]-->
    <!--<kd>0.0</kd>[> ERP <]-->
    <!--<cfmDamping>true</cfmDamping>-->
    <!--<dynamics damping="5.5" friction="1"/>-->
  </gazebo>
  <transmission name="wam/palm_yaw_trans">
    <type>transmission_interface/SimpleTransmission</type>
    <joint name="wam/palm_yaw_joint">
      <hardwareInterface>hardware_interface/PositionJointInterface</hardwareInterface>
    </joint>
    <actuator name="wam/palm_yaw_motor">
      <hardwareInterface>hardware_interface/PositionJointInterface</hardwareInterface>
      <mechanicalReduction>1</mechanicalReduction>
    </actuator>
  </transmission>
  <gazebo reference="wam/wrist_palm_link">
    <material>Gazebo/Grey</material>
  </gazebo>
  <link name="wam/wrist_palm_link">
    <inertial>
      <origin rpy="0 0 0" xyz="0.0 0.0 0.055"/>
      <mass value="0.0001"/>
      <inertia ixx="0.00010859" ixy="0.00000000" ixz="-0.00000000" iyy="0.00020683" iyz="-0.0000000" izz="0.00010851"/>
    </inertial>
    <visual>
      <material name="WAMGrey">
        <color rgba="0.7 0.7 0.7 1.0"/>
      </material>
      <origin rpy="0 0 0" xyz="0 0 0"/>
      <geometry>
        <mesh filename="package://wam_model/models/sw_meshes/wrist_palm_link_fine.stl"/>
      </geometry>
    </visual>
    <collision>
      <origin rpy="0 0 0" xyz="0 0 0"/>
      <geometry>
        <mesh filename="package://wam_model/models/sw_meshes/wrist_palm_link_convex.dae"/>
      </geometry>
    </collision>
  </link>
  <joint name="wam/wrist_palm_stump_joint" type="fixed">
    <parent link="wam/wrist_palm_link"/>
    <child link="wam/wrist_palm_stump_link"/>
    <origin rpy="0 0 0" xyz="0 0 0.06"/>
  </joint>
  <link name="wam/wrist_palm_stump_link">
    <inertial>
      <mass value="0.000001"/>
      <inertia ixx="0.0000001" ixy="0.0" ixz="0.0" iyy="0.0000001" iyz="0.0" izz="0.0000001"/>
    </inertial>
  </link>
  <joint name="wam/racquet_joint" type="fixed">
    <parent link="wam/wrist_palm_stump_link"/>
    <child link="wam/racquet_link"/>
    <!-- for racket head in straight position -->
    <!-- <origin xyz="0 0 0.01" rpy="0 0 0"/> -->
    <!-- for racket head in perpendicular starting position -->
    <origin rpy="0 0 1.5707963267948966" xyz="0 0 0.01"/>
  </joint>
  <gazebo reference="wam/racquet_link">
    <material>Gazebo/Grey</material>
  </gazebo>
  <link name="wam/racquet_link">
    <inertial>
      <mass value="0.00001"/>
      <inertia ixx="0.0001" ixy="0" ixz="0" iyy="0.0001" iyz="0" izz="0.0001"/>
    </inertial>
    <visual>
      <material name="Yellow">
        <color rgba="1.0 1.0 0.0 1.0"/>
      </material>
      <origin rpy="0 0 0" xyz="0 0 0"/>
      <geometry>
        <mesh filename="package://wam_model/models/sw_meshes/racket_new.stl" scale="1 1 1"/>
      </geometry>
    </visual>
    <collision>
      <origin rpy="0 0 0" xyz="0 0 0"/>
      <geometry>
        <mesh filename="package://wam_model/models/sw_meshes/racket_new.stl" scale="1 1 1"/>
      </geometry>
    </collision>
  </link>
  <link name="wam/racquet_hitpoint_link"/>
  <joint name="wam/racquet_hitpoint_joint" type="fixed">
    <parent link="wam/racquet_link"/>
    <child link="wam/racquet_hitpoint_link"/>
    <origin rpy="0 1.5707963267948966 0" xyz="0 0 0.520"/>
  </joint>
  <joint name="wam/wheelchair_joint" type="fixed">
    <parent link="base_link"/>
    <child link="wam/wheelchair_link"/>
    <origin rpy="0 0 0" xyz="0 0 0"/>
  </joint>
  <link name="wam/wheelchair_link">
    <inertial>
      <origin rpy="0 0 0" xyz="0.0 0.0 0"/>
      <mass value="10"/>
      <inertia ixx="0.0001" ixy="0" ixz="0" iyy="0.0001" iyz="0" izz="0.0001"/>
    </inertial>
    <visual>
      <!-- <material name="TealBlue"> -->
      <material name="Gray">
        <color rgba="0.7 0.7 0.7 1.0"/>
        <!-- <color rgba="0.212 0.459 0.533 1.0"/> -->
      </material>
      <origin rpy="0 0 0" xyz="0 0 0"/>
      <geometry>
        <mesh filename="package://wam_model/models/sw_meshes/wheelchair_cad.stl" scale="1 1 1"/>
      </geometry>
    </visual>
    <collision>
      <origin rpy="0 0 0" xyz="0 0 0"/>
      <geometry>
        <mesh filename="package://wam_model/models/sw_meshes/wheelchair_cad.stl" scale="1 1 1"/>
      </geometry>
      <surface>
        <friction>
          <ode>
            <mu>1</mu>
            <mu2>1</mu2>
          </ode>
        </friction>
      </surface>
    </collision>
  </link>
  <gazebo reference="wam/wheelchair_link">
    <turnGravityOff>0</turnGravityOff>
    <material>Gazebo/Grey</material>
  </gazebo>
  <joint name="lidar_mount_joint" type="fixed">
    <parent link="wam/wheelchair_link"/>
    <child link="lidar_mount_link"/>
    <origin rpy="0 0 0" xyz="0.19739 0 -0.10835"/>
  </joint>
  <link name="lidar_mount_link">
    <visual>
      <origin rpy="0 0 0" xyz="0 0 0"/>
      <material name="Black">
        <color rgba="0.0 0.0 0.0 1.0"/>
      </material>
      <geometry>
        <mesh filename="package://wam_model/models/sw_meshes/vlp16_mount.stl" scale="0.001 0.001 0.001"/>
      </geometry>
    </visual>
    <collision>
      <origin rpy="0 0 0" xyz="0 0 0"/>
      <geometry>
        <mesh filename="package://wam_model/models/sw_meshes/vlp16_mount.stl" scale="0.0009 0.0009 0.0009"/>
      </geometry>
    </collision>
  </link>
  <joint name="lidar_joint" type="fixed">
    <parent link="lidar_mount_link"/>
    <child link="lidar_link"/>
    <origin rpy="0 0 0" xyz="0 0 0"/>
  </joint>
  <link name="lidar_link">
    <visual>
      <material name="Blue">
        <color rgba="0.1725 0.1059 0.7019 1.0"/>
      </material>
      <origin rpy="0 0 0" xyz="0 0 0"/>
      <geometry>
        <mesh filename="package://wam_model/models/sw_meshes/vlp_16.stl" scale="0.001 0.001 0.001"/>
      </geometry>
    </visual>
    <collision>
      <origin rpy="0 0 0" xyz="0 0 0.001"/>
      <geometry>
        <mesh filename="package://wam_model/models/sw_meshes/vlp_16.stl" scale="0.0009 0.0009 0.0009"/>
      </geometry>
    </collision>
  </link>
  <material name="zed_mat">
    <color rgba="0.8 0.8 0.8 0.8"/>
  </material>
  <material name="zedm_mat">
    <color rgba="0 0 0 0.9"/>
  </material>
  <material name="zed2_mat">
    <color rgba="0.25 0.25 0.25 0.99"/>
  </material>
  <material name="zed2i_mat">
    <color rgba="0.25 0.25 0.25 0.99"/>
  </material>
  <!-- Camera mounting point (the threaded screw hole in the bottom) -->
  <link name="camera_0_base_link"/>
  <joint name="camera_0_base_joint" type="fixed">
    <parent link="wam/wheelchair_link"/>
    <child link="camera_0_base_link"/>
    <origin rpy="0 0 0" xyz="0.3333589 0 0"/>
  </joint>
  <!-- Camera Center -->
  <link name="camera_0_camera_center">
    <visual>
      <origin rpy="0 0 0" xyz="0.0 0 0"/>
      <geometry>
        <mesh filename="package://ball_calibration/models/models/zed2.stl" scale="1 1 1"/>
      </geometry>
      <material name="zed2_mat"/>
    </visual>
    <collision>
      <geometry>
        <mesh filename="package://ball_calibration/models/models/zed2.stl" scale="0.92 0.92 0.92"/>
      </geometry>
    </collision>
  </link>
  <joint name="camera_0_camera_center_joint" type="fixed">
    <parent link="camera_0_base_link"/>
    <child link="camera_0_camera_center"/>
    <origin rpy="0 0.05 0" xyz="0 0 0.015"/>
  </joint>
  <!-- Left Camera -->
  <link name="camera_0_left_camera_frame"/>
  <joint name="camera_0_left_camera_joint" type="fixed">
    <parent link="camera_0_camera_center"/>
    <child link="camera_0_left_camera_frame"/>
    <origin rpy="0 0 0" xyz="0 0.06 0"/>
  </joint>
  <link name="camera_0_left_camera_optical_frame"/>
  <joint name="camera_0_left_camera_optical_joint" type="fixed">
    <origin rpy="-1.5707963267948966 0.0 -1.5707963267948966" xyz="-0.01 0 0"/>
    <parent link="camera_0_left_camera_frame"/>
    <child link="camera_0_left_camera_optical_frame"/>
  </joint>
  <!-- Right Camera -->
  <link name="camera_0_right_camera_frame"/>
  <joint name="camera_0_right_camera_joint" type="fixed">
    <parent link="camera_0_camera_center"/>
    <child link="camera_0_right_camera_frame"/>
    <origin rpy="0 0 0" xyz="0 -0.06 0"/>
  </joint>
  <link name="camera_0_right_camera_optical_frame"/>
  <joint name="camera_0_right_camera_optical_joint" type="fixed">
    <origin rpy="-1.5707963267948966 0.0 -1.5707963267948966" xyz="-0.01 0 0"/>
    <parent link="camera_0_right_camera_frame"/>
    <child link="camera_0_right_camera_optical_frame"/>
  </joint>
  <!-- ZED2 Sensors -->
  <link name="camera_0_imu_link"/>
  <joint name="camera_0_imu_link_joint" type="fixed">
    <parent link="camera_0_left_camera_frame"/>
    <child link="camera_0_imu_link"/>
    <origin rpy="0.00138 -0.00116 -0.00176" xyz="-0.002 -0.023 -0.002"/>
  </joint>
  <link name="camera_0_mag_link"/>
  <joint name="camera_0_mag_joint" type="fixed">
    <parent link="camera_0_camera_center"/>
    <child link="camera_0_mag_link"/>
    <origin rpy="0 0 0" xyz="0 0 0"/>
  </joint>
  <link name="camera_0_baro_link"/>
  <joint name="camera_0_baro_joint" type="fixed">
    <parent link="camera_0_camera_center"/>
    <child link="camera_0_baro_link"/>
    <origin rpy="0 0 0" xyz="0 0 0"/>
  </joint>
  <link name="camera_0_temp_left_link"/>
  <joint name="camera_0_temp_left_joint" type="fixed">
    <parent link="camera_0_left_camera_frame"/>
    <child link="camera_0_temp_left_link"/>
    <origin rpy="0 0 0" xyz="0 0 0"/>
  </joint>
  <link name="camera_0_temp_right_link"/>
  <joint name="camera_0_temp_right_joint" type="fixed">
    <parent link="camera_0_right_camera_frame"/>
    <child link="camera_0_temp_right_link"/>
    <origin rpy="0 0 0" xyz="0 0 0"/>
  </joint>
  <!-- <xacro:wheelchair_rollers prefix="${prefix}"/> -->
  <!-- <xacro:wheelchair_wheels prefix="${prefix}"/> -->
  <!-- <xacro:tennis_net parent_link="static_link" /> -->
</robot>
